<robot name="ADEPT_VIPER_S650">
<link name="base_link">
    <visual>
      <origin rpy="0 0 0" xyz="0 0 0"/>
      <geometry>
        <box size="0.001 0.001 0.001"/>
      </geometry>
    </visual>
  </link>
	<link name="Adept_Viper_s650_Link1">
		<visual>
			<origin xyz="0 0 0" rpy="0 0 0"/>
			<geometry>
				<mesh filename="package://adept_common/meshes/visual/STL/binary/Adept_Viper_650_Link1.stl"/>
			</geometry>
			<material name="White">
				<color rgba="255 255 255 1.0"/>
			</material>
		</visual>
		<collision>
			<origin xyz="0 0 0" rpy="0 0 0"/>
			<geometry>
				<mesh filename="package://adept_common/meshes/collision/STL/binary/Adept_Viper_650_Link1.stl"/>
			</geometry>
			<material name="Blue">
				<color rgba="0 0 255 1.0"/>
			</material>
		</collision>
	</link>
	<link name="Adept_Viper_s650_Link2">
		<visual>
			<origin xyz="0 0 0" rpy="0 0 0"/>
			<geometry>
				<mesh filename="package://adept_common/meshes/visual/STL/binary/Adept_Viper_650_Link2.stl"/>
			</geometry>
			<material name="Red">
				<color rgba="0 0 255 1.0"/>
			</material>
		</visual>
		<collision>
			<origin xyz="0 0 0" rpy="0 0 0"/>
			<geometry>
				<mesh filename="package://adept_common/meshes/collision/STL/binary/Adept_Viper_650_Link2.stl"/>
			</geometry>
			<material name="Green">
				<color rgba="0 0 255 1.0"/>
			</material>
		</collision>
	</link>	
	<link name="Adept_Viper_s650_Link3">
		<visual>
			<origin xyz="0 0 0" rpy="0 1.5714 0"/>
			<geometry>
				<mesh filename="package://adept_common/meshes/visual/STL/binary/Adept_Viper_650_Link3.stl"/>
			</geometry>
			<material name="White">
				<color rgba="0 0 255 1.0"/>
			</material>
		</visual>
		<collision>
			<origin xyz="0 0 0" rpy="0 1.5714 0"/>
			<geometry>
				<mesh filename="package://adept_common/meshes/collision/STL/binary/Adept_Viper_650_Link3.stl"/>
			</geometry>
			<material name="Blue">
				<color rgba="0 0 255 1.0"/>
			</material>
		</collision>
	</link>
	<link name="Adept_Viper_s650_Link4">
		<visual>
			<origin xyz="0 0 0" rpy="0 -1.5714 0"/>
			<geometry>
				<mesh filename="package://adept_common/meshes/visual/STL/binary/Adept_Viper_650_Link4.stl"/>
			</geometry>
			<material name="Red">
				<color rgba="0 0 255 1.0"/>
			</material>
		</visual>
		<collision>
			<origin xyz="0 0 0" rpy="0 -1.5714 0"/>
			<geometry>
				<mesh filename="package://adept_common/meshes/collision/STL/binary/Adept_Viper_650_Link4.stl"/>
			</geometry>
			<material name="Blue">
				<color rgba="0 0 255 1.0"/>
			</material>
		</collision>
	</link>
	<link name="Adept_Viper_s650_Link5">
		<visual>
			<origin xyz="0 0 0" rpy="0 -1.5714 0"/>
			<geometry>
				<mesh filename="package://adept_common/meshes/visual/STL/binary/Adept_Viper_650_Link5.stl"/>
			</geometry>
			<material name="Blue">
				<color rgba="0 0 255 1.0"/>
			</material>
		</visual>
		<collision>
			<origin xyz="0 0 0" rpy="0 -1.5714 0"/>
			<geometry>
				<mesh filename="package://adept_common/meshes/collision/STL/binary/Adept_Viper_650_Link5.stl"/>
			</geometry>
			<material name="Blue">
				<color rgba="0 0 255 1.0"/>
			</material>
		</collision>
	</link>
	<link name="Adept_Viper_s650_Link6">
		<visual>
			<origin xyz="0 0 0" rpy="0 -1.5714 0"/>
			<geometry>
				<mesh filename="package://adept_common/meshes/visual/STL/binary/Adept_Viper_650_Link6.stl"/>
			</geometry>
			<material name="Blue">
				<color rgba="0 0 255 1.0"/>
			</material>
		</visual>
		<collision>
			<origin xyz="0 0 0" rpy="0 -1.5714 0"/>
			<geometry>
				<mesh filename="package://adept_common/meshes/collision/STL/binary/Adept_Viper_650_Link6.stl"/>
			</geometry>
			<material name="Blue">
				<color rgba="0 0 255 1.0"/>
			</material>
		</collision>
	</link>
	
	<link name="Adept_Viper_650_Interface_Plate">
		<visual>
			<origin xyz="0 0 0" rpy="0 -1.5714 0"/>
			<geometry>
				<mesh filename="package://adept_common/meshes/visual/STL/binary/Adept_Viper_650_Interface_Plate.stl"/>
			</geometry>
			<material name="Gray">
				<color rgba="100 100 100 1.0"/>
			</material>
		</visual>
		<collision>
			<origin xyz="0 0 0" rpy="0 -1.5714 0"/>
			<geometry>
				<mesh filename="package://adept_common/meshes/collision/STL/binary/Adept_Viper_650_Interface_Plate.stl"/>
			</geometry>
			<material name="Gray">
				<color rgba="100 100 100 1.0"/>
			</material>
		</collision>
	</link>
<joint name="base_link_joint" type="fixed">
    <origin rpy="0 0 0" xyz="0 0 0"/>
    <child link="Adept_Viper_s650_Link1"/>
    <parent link="base_link"/>
  </joint>
	<joint name="joint_1" type="revolute">
		<origin xyz="0 0 0.203"/>
		<parent link="Adept_Viper_s650_Link1"/>
		<child link="Adept_Viper_s650_Link2"/>
		<axis xyz="0 0 1"/>
		<limit effort="100" velocity="5.72468" lower="-2.9670" upper="2.9670"/>
	</joint>
	<joint name="joint_2" type="revolute">
		<origin xyz="0.074 0 0.18795"/>
		<parent link="Adept_Viper_s650_Link2"/>
		<child link="Adept_Viper_s650_Link3"/>
		<axis xyz="0 1 0"/>
		<limit effort="100" velocity="5.235" lower="-3.31613" upper="0.7854"/>
	</joint>
	<joint name="joint_3" type="revolute">
		<origin xyz="0.270 0 0"/>
		<parent link="Adept_Viper_s650_Link3"/>
		<child link="Adept_Viper_s650_Link4"/>
		<axis xyz="0 1 0"/>
		<limit effort="100" velocity="6.544" lower="-0.50615" upper="4.468053"/>
	</joint>
	<joint name="joint_4" type="revolute">
		<origin xyz="-0.090 0 0.295"/>
		<parent link="Adept_Viper_s650_Link4"/>
		<child link="Adept_Viper_s650_Link5"/>
		<axis xyz="0 0 1"/>
		<limit effort="100" velocity="6.544" lower="-3.31613" upper="3.316133"/>
	</joint>
	<joint name="joint_5" type="revolute">
		<origin xyz="0 0 0"/>
		<parent link="Adept_Viper_s650_Link5"/>
		<child link="Adept_Viper_s650_Link6"/>
		<axis xyz="0 1 0"/>
		<limit effort="100" velocity="6.544" lower="-2.0944" upper="2.0944"/>
	</joint>	
	<joint name="joint_6" type="revolute">
		<origin xyz="0.0 0 0.08"/>
		<parent link="Adept_Viper_s650_Link6"/>
		<child link="Adept_Viper_650_Interface_Plate"/>
		<axis xyz="0 0 1"/>
		<limit effort="100" velocity="10.47" lower="-3.1416" upper="3.1416"/>
	</joint>
	<joint name="joint_7" type="fixed">
		<origin rpy="1.55 0 0" xyz="0 0 .02"/>
		<parent link="Adept_Viper_650_Interface_Plate"/>
		<child link="palm"/>
		<axis xyz="0 0 0"/>
		<limit effort="100" velocity="10.47" lower="-3.1416" upper="3.1416"/>
	</joint>
<!--HAND HERE-->
<link name="finger_1_link_0">
    <visual>
      <origin rpy="0 0 0" xyz="0.020 0 0"/>
      <geometry>
        <mesh filename="package://robotiq_s_model_visualization/meshes/s-model_articulated/visual/link_0.STL"/>
      </geometry>
      <material name="green">
        <color rgba="0 1 0 1"/>
      </material>
    </visual>
    <collision>
      <origin rpy="0 3.1416 -1.57" xyz="-0.0455 0.0414 0.036"/>
      <geometry>
        <mesh filename="package://robotiq_s_model_visualization/meshes/s-model_articulated/collision/link_0.STL"/>
      </geometry>
      <material name="yellow">
        <color rgba="0 1 1 1"/>
      </material>
    </collision>
    <inertial>
      <origin rpy="0 0 0" xyz="0 0 0"/>
      <mass value="0.05"/>
      <inertia ixx="0.01" ixy="-0.00002" ixz="0.00001" iyy="0.0008" iyz="0" izz="0.001"/>
    </inertial>
  </link>
  <link name="finger_1_link_1">
    <visual>
      <origin rpy="0 0 -0.52" xyz="0.050 -.028 0"/>
      <geometry>
        <mesh filename="package://robotiq_s_model_visualization/meshes/s-model_articulated/visual/link_1.STL"/>
      </geometry>
      <material name="green"/>
    </visual>
    <collision>
      <origin rpy="0 0 -0.52" xyz="0.050 -.028 0"/>
      <geometry>
        <mesh filename="package://robotiq_s_model_visualization/meshes/s-model_articulated/collision/link_1.STL"/>
      </geometry>
      <material name="yellow"/>
    </collision>
    <inertial>
      <origin rpy="0 0 0" xyz="0 0 0"/>
      <mass value="0.15"/>
      <inertia ixx="0.001859" ixy="-0.000376" ixz="0.000028" iyy="0.012756" iyz="0" izz="0.0024"/>
    </inertial>
  </link>
  <link name="finger_1_link_2">
    <!--
			NOTE: This link has an offset in the z-direction based on the models that were
			used to generate grap-it poses.  With the offset below the model appears visually
			correct, but it is suspect.
			-->
    <visual>
      <origin rpy="0 0 0" xyz="0.039 0 0.0075"/>
      <geometry>
        <mesh filename="package://robotiq_s_model_visualization/meshes/s-model_articulated/visual/link_2.STL"/>
      </geometry>
      <material name="green"/>
    </visual>
    <collision>
      <origin rpy="0 0 0" xyz="0.039 0 0.0075"/>
      <geometry>
        <mesh filename="package://robotiq_s_model_visualization/meshes/s-model_articulated/collision/link_2.STL"/>
      </geometry>
      <material name="yellow"/>
    </collision>
    <inertial>
      <origin rpy="0 0 0" xyz="0 0 0"/>
      <mass value="0.15"/>
      <inertia ixx="0.001859" ixy="-0.000376" ixz="0.000028" iyy="0.012756" iyz="0" izz="0.0024"/>
    </inertial>
  </link>
  <link name="finger_1_link_3">
    <visual>
      <origin rpy="0 0 0.52" xyz="0 0 0"/>
      <geometry>
        <mesh filename="package://robotiq_s_model_visualization/meshes/s-model_articulated/visual/link_3.STL"/>
      </geometry>
      <material name="green"/>
    </visual>
    <collision>
      <origin rpy="0 0 0.52" xyz="0 0 0"/>
      <geometry>
        <mesh filename="package://robotiq_s_model_visualization/meshes/s-model_articulated/collision/link_3.STL"/>
      </geometry>
      <material name="yellow"/>
    </collision>
    <inertial>
      <origin rpy="0 0 0" xyz="0 0 0"/>
      <mass value="0.05"/>
      <inertia ixx="0.001239" ixy="-0.000251" ixz="0.000019" iyy="0.00085" iyz="0" izz="0.001632"/>
    </inertial>
  </link>
  <joint name="finger_1_joint_1" type="revolute">
    <parent link="finger_1_link_0"/>
    <child link="finger_1_link_1"/>
    <axis xyz="0 0 1"/>
    <origin rpy="0 0 0" xyz="0.020 0 0"/>
    <limit effort="100" lower="0" upper="3.1416" velocity="100"/>
  </joint>
  <joint name="finger_1_joint_2" type="revolute">
    <parent link="finger_1_link_1"/>
    <child link="finger_1_link_2"/>
    <axis xyz="0 0 1"/>
    <origin rpy="0 0 -0.52" xyz="0.050 -.028 0"/>
    <limit effort="100" lower="0" upper="3.1416" velocity="100"/>
  </joint>
  <joint name="finger_1_joint_3" type="revolute">
    <parent link="finger_1_link_2"/>
    <child link="finger_1_link_3"/>
    <axis xyz="0 0 1"/>
    <origin rpy="0 0 0" xyz="0.039 0 0"/>
    <limit effort="100" lower="0" upper="3.1416" velocity="100"/>
  </joint>
  <link name="finger_2_link_0">
    <visual>
      <origin rpy="0 0 0" xyz="0.020 0 0"/>
      <geometry>
        <mesh filename="package://robotiq_s_model_visualization/meshes/s-model_articulated/visual/link_0.STL"/>
      </geometry>
      <material name="green">
        <color rgba="0 1 0 1"/>
      </material>
    </visual>
    <collision>
      <origin rpy="0 3.1416 -1.57" xyz="-0.0455 0.0414 0.036"/>
      <geometry>
        <mesh filename="package://robotiq_s_model_visualization/meshes/s-model_articulated/collision/link_0.STL"/>
      </geometry>
      <material name="yellow">
        <color rgba="0 1 1 1"/>
      </material>
    </collision>
    <inertial>
      <origin rpy="0 0 0" xyz="0 0 0"/>
      <mass value="0.05"/>
      <inertia ixx="0.01" ixy="-0.00002" ixz="0.00001" iyy="0.0008" iyz="0" izz="0.001"/>
    </inertial>
  </link>
  <link name="finger_2_link_1">
    <visual>
      <origin rpy="0 0 -0.52" xyz="0.050 -.028 0"/>
      <geometry>
        <mesh filename="package://robotiq_s_model_visualization/meshes/s-model_articulated/visual/link_1.STL"/>
      </geometry>
      <material name="green"/>
    </visual>
    <collision>
      <origin rpy="0 0 -0.52" xyz="0.050 -.028 0"/>
      <geometry>
        <mesh filename="package://robotiq_s_model_visualization/meshes/s-model_articulated/collision/link_1.STL"/>
      </geometry>
      <material name="yellow"/>
    </collision>
    <inertial>
      <origin rpy="0 0 0" xyz="0 0 0"/>
      <mass value="0.15"/>
      <inertia ixx="0.001859" ixy="-0.000376" ixz="0.000028" iyy="0.012756" iyz="0" izz="0.0024"/>
    </inertial>
  </link>
  <link name="finger_2_link_2">
    <!--
			NOTE: This link has an offset in the z-direction based on the models that were
			used to generate grap-it poses.  With the offset below the model appears visually
			correct, but it is suspect.
			-->
    <visual>
      <origin rpy="0 0 0" xyz="0.039 0 0.0075"/>
      <geometry>
        <mesh filename="package://robotiq_s_model_visualization/meshes/s-model_articulated/visual/link_2.STL"/>
      </geometry>
      <material name="green"/>
    </visual>
    <collision>
      <origin rpy="0 0 0" xyz="0.039 0 0.0075"/>
      <geometry>
        <mesh filename="package://robotiq_s_model_visualization/meshes/s-model_articulated/collision/link_2.STL"/>
      </geometry>
      <material name="yellow"/>
    </collision>
    <inertial>
      <origin rpy="0 0 0" xyz="0 0 0"/>
      <mass value="0.15"/>
      <inertia ixx="0.001859" ixy="-0.000376" ixz="0.000028" iyy="0.012756" iyz="0" izz="0.0024"/>
    </inertial>
  </link>
  <link name="finger_2_link_3">
    <visual>
      <origin rpy="0 0 0.52" xyz="0 0 0"/>
      <geometry>
        <mesh filename="package://robotiq_s_model_visualization/meshes/s-model_articulated/visual/link_3.STL"/>
      </geometry>
      <material name="green"/>
    </visual>
    <collision>
      <origin rpy="0 0 0.52" xyz="0 0 0"/>
      <geometry>
        <mesh filename="package://robotiq_s_model_visualization/meshes/s-model_articulated/collision/link_3.STL"/>
      </geometry>
      <material name="yellow"/>
    </collision>
    <inertial>
      <origin rpy="0 0 0" xyz="0 0 0"/>
      <mass value="0.05"/>
      <inertia ixx="0.001239" ixy="-0.000251" ixz="0.000019" iyy="0.00085" iyz="0" izz="0.001632"/>
    </inertial>
  </link>
  <joint name="finger_2_joint_1" type="revolute">
    <parent link="finger_2_link_0"/>
    <child link="finger_2_link_1"/>
    <axis xyz="0 0 1"/>
    <origin rpy="0 0 0" xyz="0.020 0 0"/>
    <limit effort="100" lower="0" upper="3.1416" velocity="100"/>
  </joint>
  <joint name="finger_2_joint_2" type="revolute">
    <parent link="finger_2_link_1"/>
    <child link="finger_2_link_2"/>
    <axis xyz="0 0 1"/>
    <origin rpy="0 0 -0.52" xyz="0.050 -.028 0"/>
    <limit effort="100" lower="0" upper="3.1416" velocity="100"/>
  </joint>
  <joint name="finger_2_joint_3" type="revolute">
    <parent link="finger_2_link_2"/>
    <child link="finger_2_link_3"/>
    <axis xyz="0 0 1"/>
    <origin rpy="0 0 0" xyz="0.039 0 0"/>
    <limit effort="100" lower="0" upper="3.1416" velocity="100"/>
  </joint>
  <link name="finger_middle_link_0">
    <visual>
      <origin rpy="0 0 0" xyz="0.020 0 0"/>
      <geometry>
        <mesh filename="package://robotiq_s_model_visualization/meshes/s-model_articulated/visual/link_0.STL"/>
      </geometry>
      <material name="green">
        <color rgba="0 1 0 1"/>
      </material>
    </visual>
    <collision>
      <origin rpy="0 3.1416 -1.57" xyz="-0.0455 0.0414 0.036"/>
      <geometry>
        <mesh filename="package://robotiq_s_model_visualization/meshes/s-model_articulated/collision/link_0.STL"/>
      </geometry>
      <material name="yellow">
        <color rgba="0 1 1 1"/>
      </material>
    </collision>
    <inertial>
      <origin rpy="0 0 0" xyz="0 0 0"/>
      <mass value="0.05"/>
      <inertia ixx="0.01" ixy="-0.00002" ixz="0.00001" iyy="0.0008" iyz="0" izz="0.001"/>
    </inertial>
  </link>
  <link name="finger_middle_link_1">
    <visual>
      <origin rpy="0 0 -0.52" xyz="0.050 -.028 0"/>
      <geometry>
        <mesh filename="package://robotiq_s_model_visualization/meshes/s-model_articulated/visual/link_1.STL"/>
      </geometry>
      <material name="green"/>
    </visual>
    <collision>
      <origin rpy="0 0 -0.52" xyz="0.050 -.028 0"/>
      <geometry>
        <mesh filename="package://robotiq_s_model_visualization/meshes/s-model_articulated/collision/link_1.STL"/>
      </geometry>
      <material name="yellow"/>
    </collision>
    <inertial>
      <origin rpy="0 0 0" xyz="0 0 0"/>
      <mass value="0.15"/>
      <inertia ixx="0.001859" ixy="-0.000376" ixz="0.000028" iyy="0.012756" iyz="0" izz="0.0024"/>
    </inertial>
  </link>
  <link name="finger_middle_link_2">
    <!--
			NOTE: This link has an offset in the z-direction based on the models that were
			used to generate grap-it poses.  With the offset below the model appears visually
			correct, but it is suspect.
			-->
    <visual>
      <origin rpy="0 0 0" xyz="0.039 0 0.0075"/>
      <geometry>
        <mesh filename="package://robotiq_s_model_visualization/meshes/s-model_articulated/visual/link_2.STL"/>
      </geometry>
      <material name="green"/>
    </visual>
    <collision>
      <origin rpy="0 0 0" xyz="0.039 0 0.0075"/>
      <geometry>
        <mesh filename="package://robotiq_s_model_visualization/meshes/s-model_articulated/collision/link_2.STL"/>
      </geometry>
      <material name="yellow"/>
    </collision>
    <inertial>
      <origin rpy="0 0 0" xyz="0 0 0"/>
      <mass value="0.15"/>
      <inertia ixx="0.001859" ixy="-0.000376" ixz="0.000028" iyy="0.012756" iyz="0" izz="0.0024"/>
    </inertial>
  </link>
  <link name="finger_middle_link_3">
    <visual>
      <origin rpy="0 0 0.52" xyz="0 0 0"/>
      <geometry>
        <mesh filename="package://robotiq_s_model_visualization/meshes/s-model_articulated/visual/link_3.STL"/>
      </geometry>
      <material name="green"/>
    </visual>
    <collision>
      <origin rpy="0 0 0.52" xyz="0 0 0"/>
      <geometry>
        <mesh filename="package://robotiq_s_model_visualization/meshes/s-model_articulated/collision/link_3.STL"/>
      </geometry>
      <material name="yellow"/>
    </collision>
    <inertial>
      <origin rpy="0 0 0" xyz="0 0 0"/>
      <mass value="0.05"/>
      <inertia ixx="0.001239" ixy="-0.000251" ixz="0.000019" iyy="0.00085" iyz="0" izz="0.001632"/>
    </inertial>
  </link>
  <joint name="finger_middle_joint_1" type="revolute">
    <parent link="finger_middle_link_0"/>
    <child link="finger_middle_link_1"/>
    <axis xyz="0 0 1"/>
    <origin rpy="0 0 0" xyz="0.020 0 0"/>
    <limit effort="100" lower="0" upper="3.1416" velocity="100"/>
  </joint>
  <joint name="finger_middle_joint_2" type="revolute">
    <parent link="finger_middle_link_1"/>
    <child link="finger_middle_link_2"/>
    <axis xyz="0 0 1"/>
    <origin rpy="0 0 -0.52" xyz="0.050 -.028 0"/>
    <limit effort="100" lower="0" upper="3.1416" velocity="100"/>
  </joint>
  <joint name="finger_middle_joint_3" type="revolute">
    <parent link="finger_middle_link_2"/>
    <child link="finger_middle_link_3"/>
    <axis xyz="0 0 1"/>
    <origin rpy="0 0 0" xyz="0.039 0 0"/>
    <limit effort="100" lower="0" upper="3.1416" velocity="100"/>
  </joint>
  <link name="palm">
    <visual>
      <geometry>
        <mesh filename="package://robotiq_s_model_visualization/meshes/s-model_articulated/visual/palm.STL"/>
      </geometry>
      <material name="green">
        <color rgba="0 1 0 1"/>
      </material>
    </visual>
    <collision>
      <geometry>
        <mesh filename="package://robotiq_s_model_visualization/meshes/s-model_articulated/collision/palm.STL"/>
      </geometry>
      <material name="yellow">
        <color rgba="0 1 1 1"/>
      </material>
    </collision>
  </link>
  <inertial>
    <origin rpy="0 0 0" xyz="0 0 0"/>
    <mass value="1.3"/>
    <inertia ixx="0.006012" ixy="0.000079" ixz="-0.00024" iyy="0.012892" iyz="0" izz="0.002435"/>
  </inertial>
  <joint name="palm_finger_1_joint" type="revolute">
    <parent link="palm"/>
    <child link="finger_1_link_0"/>
    <axis xyz="0 1 0"/>
    <origin rpy="0 3.1416 -1.57" xyz="-0.0455 0.0214 0.036"/>
    <limit effort="100" lower="-0.16" upper="0.25" velocity="100"/>
  </joint>
  <joint name="palm_finger_2_joint" type="revolute">
    <parent link="palm"/>
    <child link="finger_2_link_0"/>
    <axis xyz="0 1 0"/>
    <origin rpy="0 3.1416 -1.57" xyz="-0.0455 0.0214 -0.036"/>
    <limit effort="100" lower="-0.25" upper="0.16" velocity="100"/>
  </joint>
  <joint name="palm_finger_middle_joint" type="fixed">
    <parent link="palm"/>
    <child link="finger_middle_link_0"/>
    <axis xyz="0 0 1"/>
    <origin rpy="0 0 1.57" xyz="0.0455 0.0214 0"/>
  </joint>
</robot>
